Workbook

Sheet Step1_Inward
A1: Date | B1: Month | C1: In_Lot | D1: Aging | E1: PCB Type | F1: Quantity Received | G1: Operator Name | H1: Atomberg quantity | I1: shortage
A2: 45569 | B2: =TEXT(A2,"mmm-yy") -> Oct-24 | C2: Lot 10 | D2: =if(C2=Step2_Segregation!C2,DATEDIF(A2,Today(), "Y") & " Years, " & DATEDIF(A2, Today(), "YM") & " Months, " & DATEDIF(A2, Today(), "MD") & " Days","")
A3: 45597 | B3: =TEXT(A3,"mmm-yy") -> Nov-24 | C3: Lot 72
A4: 45621 | B4: =TEXT(A4,"mmm-yy") -> Nov-24 | C4: Lot 72 | E4: GV3 Digital PCB | F4: 657 | G4: Rahul gupta | H4: 664 | I4: 7pcb
A5: 45621 | B5: =TEXT(A5,"mmm-yy") -> Nov-24 | C5: Lot 72 | E5: GV2 Remote Main PCB | F5: 528 | G5: Rahul gupta | H5: 528
A6: 45621 | B6: =TEXT(A6,"mmm-yy") -> Nov-24 | C6: Lot 72 | E6: GV4 Studio+ Remote PCB | F6: 233 | G6: Rahul gupta | H6: 231 | I6: 2+ pcb
A7: 45621 | B7: =TEXT(A7,"mmm-yy") -> Nov-24 | C7: Lot 72 | E7: GV3 Power PCB | F7: 606 | G7: Rahul gupta | H7: 606

Sheet Step2_Segregation
A1: Date | B1: Month | C1: In_Lot | D1: Aging | E1: PCB Type | F1: Repairable Quantity | G1: Scrap Quantity | H1: Quantity Inspected | I1: Operator Name
A2: 45601 | B2: =TEXT(A2,"mmm-yy") -> Nov-24 | C2: Lot 71 | D2: =if(C2=Step1_Inward!C2,DATEDIF(Step1_Inward!A2,A2, "Y") & " Years, " & DATEDIF(Step1_Inward!A2,A2, "YM") & " Months, " & DATEDIF(Step1_Inward!A2,A2, "MD") & " Days","") | E2: GV3 Digital PCB | F2: 1580 | G2: 109 | H2: =SUM(F2:G2) -> 1689 | I2: Amit ghabale
A3: 45601 | B3: =TEXT(A3,"mmm-yy") -> Nov-24 | C3: Lot 71 | D3: =if(C3=Step1_Inward!C3,DATEDIF(Step1_Inward!A3,A3, "Y") & " Years, " & DATEDIF(Step1_Inward!A3,A3, "YM") & " Months, " & DATEDIF(Step1_Inward!A3,A3, "MD") & " Days","") | E3: GV3 Digital PCB | F3: 506 | H3: 506 | I3: Rahul gupta
A4: 45605 | B4: =TEXT(A4,"mmm-yy") -> Nov-24 | C4: Lot 71 | D4: =if(C4=Step1_Inward!C4,DATEDIF(Step1_Inward!A4,A4, "Y") & " Years, " & DATEDIF(Step1_Inward!A4,A4, "YM") & " Months, " & DATEDIF(Step1_Inward!A4,A4, "MD") & " Days","") | E4: GV3 Power PCB | F4: 142 | H4: 142 | I4: Mayuri
A5: 45619 | B5: =TEXT(A5,"mmm-yy") -> Nov-24 | C5: Lot 72 | E5: GV4 Ozeo Remote PCB | F5: 234 | G5: 75 | H5: =sum(F5+G5) -> 309 | I5: Rahul gupta
A6: 45621 | B6: =TEXT(A6,"mmm-yy") -> Nov-24 | C6: Lot 72 | E6: GV4 Ozeo Remote PCB | F6: 140 | G6: 79 | H6: =sum(F6+G6) -> 219 | I6: Rahul gupta | J6: vijay screw open
A7: 45621 | B7: =TEXT(A7,"mmm-yy") -> Nov-24 | C7: Lot 72 | E7: GV3 Power PCB | F7: 442 | G7: 164 | H7: =sum(F7+G7) -> 606 | I7: Rahul gupta | J7: vijay screw open
A8: 45621 | B8: =TEXT(A8,"mmm-yy") -> Nov-24 | C8: Lot 72 | E8: GV4 Studio+ Remote PCB | F8: 173 | G8: 60 | H8: =sum(F8+G8) -> 233 | I8: Rahul gupta | J8: vijay screw open
A9: 45626 | B9: =TEXT(A9,"mmm-yy") -> Nov-24 | C9: Lot 73 | E9: GV2 Remote Main PCB | F9: 344 | I9: All
A10: 45626 | B10: =TEXT(A10,"mmm-yy") -> Nov-24 | C10: Lot 73 | E10: GV2 Regulator | F10: 310 | I10: All
A11: 45626 | B11: =TEXT(A11,"mmm-yy") -> Nov-24 | C11: Lot 73 | E11: GV3 Digital PCB | F11: 459 | I11: All
A12: 45626 | B12: =TEXT(A12,"mmm-yy") -> Nov-24 | C12: Lot 73 | E12: GV3 Digital PCB | F12: 88 | I12: All | J12: OLD BARCODE
A13: 45626 | B13: =TEXT(A13,"mmm-yy") -> Nov-24 | C13: Lot 73 | E13: GV2 Remote Main PCB | F13: 64 | I13: All | J13: OLD BARCODE
A14: 45626 | B14: =TEXT(A14,"mmm-yy") -> Nov-24 | C14: Lot 73 | E14: GV3 Smart PCB | F14: 186 | I14: All
A15: 45626 | B15: =TEXT(A15,"mmm-yy") -> Nov-24 | C15: Lot 73 | E15: GV4 Studio+ Remote PCB | F15: 163 | I15: All
A16: 45626 | B16: =TEXT(A16,"mmm-yy") -> Nov-24 | C16: Lot 73 | E16: GV4 Ozeo Remote PCB | F16: 52 | I16: All
A17: 45626 | B17: =TEXT(A17,"mmm-yy") -> Nov-24 | C17: Lot 73 | E17: GV4 Alpha Regulator PCB | F17: 192 | I17: All
A18: 45626 | B18: =TEXT(A18,"mmm-yy") -> Nov-24 | C18: Lot 73 | E18: GV4 Ozeo Remote PCB | F18: 80 | I18: All | J18: OLD BARCODE
A19: 45626 | B19: =TEXT(A19,"mmm-yy") -> Nov-24 | C19: Lot 73 | E19: GV4 Ozeo Remote PCB | F19: 37 | I19: All
A20: 45626 | B20: =TEXT(A20,"mmm-yy") -> Nov-24 | C20: Lot 73 | E20: GV2 Remote Main PCB | F20: 381 | I20: All
A21: 45628 | B21: =TEXT(A21,"mmm-yy") -> Dec-24 | C21: Lot 73 | E21: GV3 Power PCB | F21: 652 | I21: Vijay kumar | J21: GV3 power 6 screw open and segregation prajkta and mauri
A22: 45629 | B22: =TEXT(A22,"mmm-yy") -> Dec-24 | C22: Lot 73 | E22: GV3 Power PCB | F22: 227 | G22: 19 | H22: =sum(F22+G22) -> 246 | I22: Vijay kumar | J22: GV3 power 6 screw open and segregation
A23: 45637 | B23: =TEXT(A23,"mmm-yy") -> Dec-24 | C23: Lot 74 | E23: GV3 Digital PCB | F23: 1287 | I23: Rahul gupta
A24: 45637 | B24: =TEXT(A24,"mmm-yy") -> Dec-24 | C24: Lot 74 | E24: GV2 Remote Main PCB | F24: 707 | I24: Vijay kumar
A25: 45638 | B25: =TEXT(A25,"mmm-yy") -> Dec-24 | C25: Lot 74 | E25: GV4 Studio+ Remote PCB | F25: 155 | G25: 13 | H25: =sum(F25+G25) -> 168 | I25: Rahul gupta
A26: 45638 | B26: =TEXT(A26,"mmm-yy") -> Dec-24 | C26: Lot 74 | E26: GV4 Alpha Regulator PCB | F26: 158 | G26: 11 | H26: =sum(F26+G26) -> 169 | I26: Rahul gupta
A27: 45638 | B27: =TEXT(A27,"mmm-yy") -> Dec-24 | C27: Lot 74 | E27: GV4 Ozeo Remote PCB | F27: 72 | G27: 4 | H27: =sum(F27+G27) -> 76 | I27: Rahul gupta
A28: 45640 | B28: =TEXT(A28,"mmm-yy") -> Dec-24 | C28: Lot 74 | E28: GV3 Power PCB | F28: 1624 | G28: 100 | H28: =sum(F28+G28) -> 1724 | I28: Amit ghabale | J28: dadasaheb
A29: 45642 | B29: =TEXT(A29,"mmm-yy") -> Dec-24 | C29: Lot 74 | E29: GV3 Power PCB | F29: 950 | G29: 48 | H29: =sum(F29+G29) -> 998 | I29: Akash prasad | J29: amit and mayuri
A30: 45643 | B30: =TEXT(A30,"mmm-yy") -> Dec-24 | C30: Lot 74 | E30: GV3 Power PCB | F30: 149 | G30: 11 | H30: =sum(F30+G30) -> 160 | I30: Mayuri
A31: 45654 | B31: =TEXT(A31,"mmm-yy") -> Dec-24 | E31: GV3 Digital PCB | F31: 1672 | I31: All
A32: 45654 | B32: =TEXT(A32,"mmm-yy") -> Dec-24 | E32: GV3 Digital PCB | F32: 416 | I32: All | J32: old barcode
A33: 45654 | B33: =TEXT(A33,"mmm-yy") -> Dec-24 | E33: GV3 Smart PCB | F33: 240 | I33: All
A34: 45656 | B34: =TEXT(A34,"mmm-yy") -> Dec-24 | C34: 75/76 | E34: GV2 Remote Main PCB | F34: 1665 | I34: Akash prasad
A35: 45656 | B35: =TEXT(A35,"mmm-yy") -> Dec-24 | C35: 75/76 | E35: GV2 Remote Main PCB | F35: 120 | I35: Akash prasad | J35: old barcode
A36: 45656 | B36: =TEXT(A36,"mmm-yy") -> Dec-24 | C36: 75/76 | E36: GV2 Remote Main PCB | F36: 140 | I36: Rahul gupta
A37: 45668 | B37: =TEXT(A37,"mmm-yy") -> Jan-25 | C37: 77 | E37: GV2 Remote Main PCB | F37: 1011 | G37: 43 | I37: All | J37: STM PCB =440 Nuvoton PCB =404 Regular PCB =124
A38: 45678 | B38: =TEXT(A38,"mmm-yy") -> Jan-25 | C38: 78 | E38: GV2 Remote Main PCB | F38: 807 | I38: All
A39: 45679 | B39: =TEXT(A39,"mmm-yy") -> Jan-25 | C39: 78 | E39: GV3 Digital PCB | F39: 350 | I39: Rahul gupta
A40: 45680 | B40: =TEXT(A40,"mmm-yy") -> Jan-25 | C40: 78 | E40: GV3 Power PCB | F40: 685 | G40: 185 | I40: Amit ghabale | J40: screw open @Mayuri Elc @nilamdhanawade Elc @~King____Dadasaheb____0001
...

Sheet Step3_Programming
A1: Date | B1: Month | C1: In_Lot | D1: Aging | E1: PCB Type | F1: Code Ok | G1: Code Not Ok | H1: Total PCBs | I1: Operator Name
A2: 45602 | B2: =TEXT(A2,"mmm-yy") -> Nov-24 | D2: =if(C2=Step2_Segregation!C2,DATEDIF(Step2_Segregation!A2,Today(), "Y") & " Years, " & DATEDIF(Step2_Segregation!A2, Today(), "YM") & " Months, " & DATEDIF(Step2_Segregation!A2, Today(), "MD") & " Days","") | E2: GV3 Digital PCB | F2: 1000 | G2: 180 | H2: =SUM(F2:G2) -> 1180 | I2: Swarupa Vishwakarma
A3: 45603 | B3: =TEXT(A3,"mmm-yy") -> Nov-24 | E3: GV3 Digital PCB | F3: 380 | G3: 20 | H3: =SUM(F3:G3) -> 400 | I3: Nilam dhanawade
A4: 45603 | B4: =TEXT(A4,"mmm-yy") -> Nov-24 | E4: GV4 Alpha Regulator PCB | F4: 650 | G4: 39 | H4: =SUM(F4:G4) -> 689 | I4: Nilam dhanawade
A5: 45604 | B5: =TEXT(A5,"mmm-yy") -> Nov-24 | E5: GV4 Alpha Regulator PCB | F5: 990 | G5: 120 | H5: =SUM(F5:G5) -> 1110 | I5: Nilam dhanawade
A6: 45605 | B6: =TEXT(A6,"mmm-yy") -> Nov-24 | E6: GV2 Remote Main PCB | F6: 980 | G6: 185 | H6: =SUM(F6:G6) -> 1165 | I6: Nilam dhanawade
A7: 45607 | B7: =TEXT(A7,"mmm-yy") -> Nov-24 | E7: GV2 Remote Main PCB | F7: 112 | G7: 12 | H7: =SUM(F7:G7) -> 124 | I7: Nilam dhanawade
A8: 45607 | B8: =TEXT(A8,"mmm-yy") -> Nov-24 | E8: GV3 Digital PCB | F8: 600 | G8: 46 | H8: =SUM(F8:G8) -> 646 | I8: Nilam dhanawade
A9: 45621 | B9: =TEXT(A9,"mmm-yy") -> Nov-24 | C9: 72 | E9: GV3 Digital PCB | F9: 297 | G9: 46 | H9: =SUM(F9:G9) -> 343 | I9: Nilam dhanawade
A10: 45621 | B10: =TEXT(A10,"mmm-yy") -> Nov-24 | C10: 72 | E10: GV2 Regulator | F10: 118 | G10: 55 | H10: =SUM(F10:G10) -> 173 | I10: Nilam dhanawade
A11: 45621 | B11: =TEXT(A11,"mmm-yy") -> Nov-24 | C11: 72 | E11: GV2 Remote Main PCB | F11: 147 | G11: 26 | H11: =SUM(F11:G11) -> 173 | I11: Nilam dhanawade
A12: 45621 | B12: =TEXT(A12,"mmm-yy") -> Nov-24 | C12: 72 | E12: GV4 Alpha Regulator PCB | F12: 80 | G12: 3 | H12: =SUM(F12:G12) -> 83 | I12: Nilam dhanawade
A13: 45621 | B13: =TEXT(A13,"mmm-yy") -> Nov-24 | C13: 72 | E13: GV4 Studio+ Remote PCB | F13: 66 | G13: 11 | H13: =SUM(F13:G13) -> 77 | I13: Nilam dhanawade
A14: 45621 | B14: =TEXT(A14,"mmm-yy") -> Nov-24 | C14: 72 | E14: GV4 Ozeo Remote PCB | F14: 4 | G14: 9 | H14: =SUM(F14:G14) -> 13 | I14: Nilam dhanawade
A15: 45628 | B15: =TEXT(A15,"mmm-yy") -> Dec-24 | C15: 73 | E15: GV3 Digital PCB | F15: 417 | G15: 26 | H15: =SUM(F15:G15) -> 443 | I15: Nilam dhanawade
A16: 45628 | B16: =TEXT(A16,"mmm-yy") -> Dec-24 | C16: 73 | E16: GV2 Remote Main PCB | F16: 311 | G16: 6 | H16: =SUM(F16:G16) -> 317 | I16: Nilam dhanawade
A17: 45628 | B17: =TEXT(A17,"mmm-yy") -> Dec-24 | C17: 73 | E17: GV2 Regulator | F17: 341 | G17: 2 | H17: =SUM(F17:G17) -> 343 | I17: Nilam dhanawade
A18: 45629 | B18: =TEXT(A18,"mmm-yy") -> Dec-24 | C18: 73 | E18: GV4 Ozeo Remote PCB | F18: 79 | G18: 1 | H18: =SUM(F18:G18) -> 80 | I18: Nilam dhanawade
A19: 45629 | B19: =TEXT(A19,"mmm-yy") -> Dec-24 | C19: 73 | E19: GV4 Studio+ Remote PCB | F19: 103 | G19: 2 | H19: =SUM(F19:G19) -> 105 | I19: Nilam dhanawade
A20: 45629 | B20: =TEXT(A20,"mmm-yy") -> Dec-24 | C20: 73 | E20: GV4 Alpha Regulator PCB | F20: 167 | H20: =SUM(F20:G20) -> 167 | I20: Nilam dhanawade
A21: 45638 | B21: =TEXT(A21,"mmm-yy") -> Dec-24 | C21: 74 | E21: GV3 Digital PCB | F21: 713 | G21: 182 | H21: =SUM(F21:G21) -> 895 | I21: Nilam dhanawade
A22: 45638 | B22: =TEXT(A22,"mmm-yy") -> Dec-24 | C22: 74 | E22: GV2 Remote Main PCB | F22: 182 | G22: 33 | H22: =SUM(F22:G22) -> 215 | I22: Nilam dhanawade
A23: 45638 | B23: =TEXT(A23,"mmm-yy") -> Dec-24 | C23: 74 | E23: GV2 Remote Main PCB | F23: 254 | G23: 28 | H23: =SUM(F23:G23) -> 282 | I23: Nilam dhanawade
A24: 45639 | B24: =TEXT(A24,"mmm-yy") -> Dec-24 | C24: 74 | E24: GV4 Studio+ Remote PCB | F24: 144 | G24: 10 | H24: =SUM(F24:G24) -> 154 | I24: Nilam dhanawade
A25: 45639 | B25: =TEXT(A25,"mmm-yy") -> Dec-24 | C25: 74 | E25: GV4 Alpha Regulator PCB | F25: 150 | G25: 8 | H25: =SUM(F25:G25) -> 158 | I25: Nilam dhanawade
A26: 45639 | B26: =TEXT(A26,"mmm-yy") -> Dec-24 | C26: 74 | E26: GV4 Ozeo Remote PCB | F26: 58 | G26: 16 | H26: =SUM(F26:G26) -> 74 | I26: Nilam dhanawade
A27: 45639 | B27: =TEXT(A27,"mmm-yy") -> Dec-24 | C27: 74 | E27: GV2 Remote Main PCB | F27: 76 | G27: 7 | H27: =SUM(F27:G27) -> 83 | I27: Nilam dhanawade
A28: 45656 | B28: =TEXT(A28,"mmm-yy") -> Dec-24 | C28: 75/76 | E28: GV3 Digital PCB | F28: 1365 | G28: 282 | H28: =SUM(F28:G28) -> 1647 | I28: Nilam dhanawade
A29: 45656 | B29: =TEXT(A29,"mmm-yy") -> Dec-24 | C29: 75/76 | E29: GV2 Remote Main PCB | F29: 135 | H29: =SUM(F29:G29) -> 135 | I29: Nilam dhanawade
A30: 45657 | B30: =TEXT(A30,"mmm-yy") -> Dec-24 | C30: 75/76 | E30: GV2 Remote Main PCB | F30: 591 | G30: 87 | H30: =SUM(F30:G30) -> 678 | I30: Nilam dhanawade
A31: 45657 | B31: =TEXT(A31,"mmm-yy") -> Dec-24 | C31: 75/76 | E31: GV2 Remote Main PCB | F31: 527 | G31: 53 | H31: =SUM(F31:G31) -> 580 | I31: Nilam dhanawade
A32: 45659 | B32: =TEXT(A32,"mmm-yy") -> Jan-25 | C32: 75/76 | E32: GV4 Studio+ Remote PCB | F32: 170 | G32: 20 | H32: =SUM(F32:G32) -> 190 | I32: Nilam dhanawade
A33: 45659 | B33: =TEXT(A33,"mmm-yy") -> Jan-25 | C33: 75/76 | E33: GV4 Alpha Regulator PCB | F33: 269 | G33: 25 | H33: =SUM(F33:G33) -> 294 | I33: Nilam dhanawade
A34: 45659 | B34: =TEXT(A34,"mmm-yy") -> Jan-25 | C34: 75/76 | E34: GV4 Ozeo Remote PCB | F34: 161 | G34: 5 | H34: =SUM(F34:G34) -> 166 | I34: Nilam dhanawade
A35: 45659 | B35: =TEXT(A35,"mmm-yy") -> Jan-25 | C35: 75/76 | E35: GV3 Digital PCB | F35: 175 | H35: =SUM(F35:G35) -> 175 | I35: Nilam dhanawade
A36: 45670 | B36: =TEXT(A36,"mmm-yy") -> Jan-25 | C36: 77 | E36: GV2 Remote Main PCB | F36: 705 | G36: 155 | H36: =SUM(F36:G36) -> 860 | I36: Nilam dhanawade
A37: 45671 | B37: =TEXT(A37,"mmm-yy") -> Jan-25 | C37: 77 | E37: GV3 Digital PCB | F37: 670 | G37: 247 | H37: =SUM(F37:G37) -> 917 | I37: Nilam dhanawade
A38: 45671 | B38: =TEXT(A38,"mmm-yy") -> Jan-25 | C38: 77 | E38: GV4 Ozeo Remote PCB | F38: 20 | G38: 6 | H38: =SUM(F38:G38) -> 26 | I38: Nilam dhanawade
A39: 45671 | B39: =TEXT(A39,"mmm-yy") -> Jan-25 | C39: 77 | E39: GV4 Alpha Regulator PCB | F39: 67 | G39: 11 | H39: =SUM(F39:G39) -> 78 | I39: Nilam dhanawade
A40: 45671 | B40: =TEXT(A40,"mmm-yy") -> Jan-25 | C40: 77 | E40: GV4 Studio+ Remote PCB | F40: 83 | G40: 16 | H40: =SUM(F40:G40) -> 99 | I40: Nilam dhanawade
...

Sheet Step4_1st Testing
A1: Date | B1: Month | C1: In_Lot | D1: PCB Type | E1: Quantity Passed (OK) | F1: Quantity Failed | G1: Quantity Tested | H1: Operator Name | I1: Remark
A2: 45600 | B2: =TEXT(A2,"mmm-yy") -> Nov-24 | D2: GV2 Remote Main PCB | E2: 38 | F2: 186 | G2: =SUM(E2:F2) -> 224 | H2: Rahul gupta
A3: 45601 | B3: =TEXT(A3,"mmm-yy") -> Nov-24 | D3: GV2 Remote Main PCB | E3: 150 | F3: 142 | G3: =SUM(E3:F3) -> 292 | H3: Prajkta Sutar
A4: 45602 | B4: =TEXT(A4,"mmm-yy") -> Nov-24 | D4: GV2 Remote Main PCB | E4: 245 | F4: 255 | G4: =SUM(E4:F4) -> 500 | H4: Akash prasad
A5: 45603 | B5: =TEXT(A5,"mmm-yy") -> Nov-24 | D5: GV3 Digital PCB | E5: 220 | F5: 230 | G5: =SUM(E5:F5) -> 450 | H5: Akash prasad
A6: 45604 | B6: =TEXT(A6,"mmm-yy") -> Nov-24 | D6: GV4 Studio+ Remote PCB | E6: 95 | F6: 215 | G6: =SUM(E6:F6) -> 310 | H6: Amit ghabale
A7: 45604 | B7: =TEXT(A7,"mmm-yy") -> Nov-24 | D7: GV2 Remote Main PCB | E7: 165 | G7: =SUM(E7:F7) -> 165 | H7: Amit ghabale
A8: 45604 | B8: =TEXT(A8,"mmm-yy") -> Nov-24 | D8: GV4 Studio+ Remote PCB | E8: 130 | F8: 210 | G8: =SUM(E8:F8) -> 340 | H8: Prajkta Sutar
A9: 45604 | B9: =TEXT(A9,"mmm-yy") -> Nov-24 | D9: GV3 Digital PCB | E9: 80 | F9: 60 | G9: =SUM(E9:F9) -> 140 | H9: Akash prasad
A10: 45605 | B10: =TEXT(A10,"mmm-yy") -> Nov-24 | D10: GV4 Studio+ Remote PCB | E10: 231 | F10: 132 | G10: =SUM(E10:F10) -> 363 | H10: Prajkta Sutar
A11: 45605 | B11: =TEXT(A11,"mmm-yy") -> Nov-24 | D11: GV4 Studio+ Remote PCB | E11: 170 | F11: 245 | G11: =SUM(E11:F11) -> 415 | H11: Amit ghabale
A12: 45605 | B12: =TEXT(A12,"mmm-yy") -> Nov-24 | D12: GV3 Digital PCB | E12: 143 | F12: 50 | G12: =SUM(E12:F12) -> 193 | H12: Mayuri
A13: 45607 | B13: =TEXT(A13,"mmm-yy") -> Nov-24 | D13: GV4 Studio+ Remote PCB | E13: 120 | F13: 230 | G13: =SUM(E13:F13) -> 350 | H13: Amit ghabale
A14: 45607 | B14: =TEXT(A14,"mmm-yy") -> Nov-24 | D14: GV3 Digital PCB | E14: 265 | F14: 290 | G14: =SUM(E14:F14) -> 555 | H14: Akash prasad
A15: 45607 | B15: =TEXT(A15,"mmm-yy") -> Nov-24 | D15: GV2 Remote Main PCB | E15: 255 | F15: 232 | G15: =SUM(E15:F15) -> 487 | H15: Poonam lokhande
A16: 45607 | B16: =TEXT(A16,"mmm-yy") -> Nov-24 | D16: GV4 Alpha Regulator PCB | E16: 111 | F16: 101 | G16: =SUM(E16:F16) -> 212 | H16: Mayuri
A17: 45608 | B17: =TEXT(A17,"mmm-yy") -> Nov-24 | D17: GV2 Remote Main PCB | E17: 59 | F17: 63 | G17: =SUM(E17:F17) -> 122 | H17: Mayuri
A18: 45609 | B18: =TEXT(A18,"mmm-yy") -> Nov-24 | D18: GV2 Remote Main PCB | E18: 10 | F18: 10 | G18: =SUM(E18:F18) -> 20 | H18: Mayuri
A19: 45611 | B19: =TEXT(A19,"mmm-yy") -> Nov-24 | D19: GV3 Power PCB | E19: 170 | F19: 8 | G19: =SUM(E19:F19) -> 178 | H19: Poonam lokhande
... A21: 45611 | B21: =TEXT(A21,"mmm-yy") -> Nov-24 | D21: GV3 Power PCB | E21: 50 | F21: 5 | G21: =SUM(E21:F21) -> 55 | H21: Mayuri
A22: 45612 | B22: =TEXT(A22,"mmm-yy") -> Nov-24 | D22: GV3 Power PCB | E22: 75 | F22: 5 | G22: =SUM(E22:F22) -> 80 | H22: Mayuri | I22: debug testing pcb
A23: 45612 | B23: =TEXT(A23,"mmm-yy") -> Nov-24 | D23: GV3 Digital PCB | E23: 140 | F23: 4 | G23: =SUM(E23:F23) -> 144 | H23: Swarupa Vishwakarma | I23: debug testing pcb
A24: 45612 | B24: =TEXT(A24,"mmm-yy") -> Nov-24 | D24: GV3 Power PCB | E24: 48 | G24: =SUM(E24:F24) -> 48 | H24: Poonam lokhande | I24: debug testing pcb
A25: 45614 | B25: =TEXT(A25,"mmm-yy") -> Nov-24 | D25: GV3 Digital PCB | E25: 150 | F25: 5 | G25: =SUM(E25:F25) -> 155 | H25: Swarupa Vishwakarma | I25: debug testing pcb
A26: 45623 | B26: =TEXT(A26,"mmm-yy") -> Nov-24 | C26: 72 | D26: GV4 Alpha Regulator PCB | E26: 37 | F26: 43 | G26: =SUM(E26:F26) -> 80 | H26: Mayuri
A27: 45623 | B27: =TEXT(A27,"mmm-yy") -> Nov-24 | C27: 72 | D27: GV4 Studio+ Remote PCB | E27: 17 | F27: 45 | G27: =SUM(E27:F27) -> 62 | H27: Mayuri
A28: 45623 | B28: =TEXT(A28,"mmm-yy") -> Nov-24 | C28: 72 | D28: GV2 Regulator | E28: 30 | F28: 88 | G28: =SUM(E28:F28) -> 118 | H28: Mayuri
A29: 45629 | B29: =TEXT(A29,"mmm-yy") -> Dec-24 | C29: 73 | D29: GV2 Remote Main PCB | E29: 300 | F29: 12 | G29: =SUM(E29:F29) -> 312 | H29: Prajkta Sutar
A30: 45629 | B30: =TEXT(A30,"mmm-yy") -> Dec-24 | C30: 73 | D30: GV2 Remote Main PCB | E30: 250 | F30: 7 | G30: =SUM(E30:F30) -> 257 | H30: Mayuri
A31: 45630 | B31: =TEXT(A31,"mmm-yy") -> Dec-24 | C31: 73 | D31: GV2 Remote Main PCB | E31: 83 | F31: 3 | G31: =SUM(E31:F31) -> 86 | H31: Mayuri
A32: 45630 | B32: =TEXT(A32,"mmm-yy") -> Dec-24 | C32: 73 | D32: GV4 Alpha Regulator PCB | E32: 73 | F32: 23 | G32: =SUM(E32:F32) -> 96 | H32: Mayuri
A33: 45631 | B33: =TEXT(A33,"mmm-yy") -> Dec-24 | D33: GV4 Studio+ Remote PCB | E33: 85 | F33: 18 | G33: =SUM(E33:F33) -> 103 | H33: Prajkta Sutar
A34: 45631 | B34: =TEXT(A34,"mmm-yy") -> Dec-24 | D34: GV4 Ozeo Remote PCB | E34: 73 | F34: 6 | G34: =SUM(E34:F34) -> 79 | H34: Prajkta Sutar
A35: 45638 | B35: =TEXT(A35,"mmm-yy") -> Dec-24 | D35: GV3 Digital PCB | E35: 170 | F35: 100 | G35: =SUM(E35:F35) -> 270 | H35: Mayuri
A36: 45639 | B36: =TEXT(A36,"mmm-yy") -> Dec-24 | D36: GV3 Digital PCB | E36: 183 | F36: 111 | G36: =SUM(E36:F36) -> 294 | H36: Mayuri
A37: 45639 | B37: =TEXT(A37,"mmm-yy") -> Dec-24 | D37: GV2 Remote Main PCB | E37: 143 | F37: 100 | G37: =SUM(E37:F37) -> 243 | H37: Prajkta Sutar
A38: 45639 | B38: =TEXT(A38,"mmm-yy") -> Dec-24 | D38: GV2 Remote Main PCB | E38: 109 | F38: 72 | G38: =SUM(E38:F38) -> 181 | H38: Prajkta Sutar
A39: 45640 | B39: =TEXT(A39,"mmm-yy") -> Dec-24 | C39: 74 | D39: GV4 Alpha Regulator PCB | E39: 104 | F39: 58 | G39: =SUM(E39:F39) -> 162 | H39: Mayuri
A40: 45640 | B40: =TEXT(A40,"mmm-yy") -> Dec-24 | C40: 74 | D40: GV4 Ozeo Remote PCB | E40: 51 | F40: 7 | G40: =SUM(E40:F40) -> 58 | H40: Mayuri
A41: 45642 | B41: =TEXT(A41,"mmm-yy") -> Dec-24 | C41: 74 | D41: GV3 Power PCB | E41: 600 | F41: 75 | G41: =SUM(E41:F41) -> 675 | H41: Nilam dhanawade
...

Sheet Step5_Debug
A1: Date | B1: Month | C1: In_Lot | D1: PCB Type | E1: Quantity Debug OK | F1: Critical Quantity | G1: Scrap PCBs | H1: Total Debug Quantity | I1: Operator Name | J1: Remark
A2: 45604 | B2: =TEXT(A2,"mmm-yy") -> Nov-24 | D2: GV2 Remote Main PCB | H2: =SUM(E2:G2) -> 0 | I2: Poonam lokhande | J2: Gv2 QC reparing pcb = 350 | K2: =E2/H2 -> #DIV/0!
A3: 45605 | B3: =TEXT(A3,"mmm-yy") -> Nov-24 | D3: GV4 Studio+ Remote PCB | I3: Poonam lokhande | J3: Gv4 QC reparing ok pcb = 96 | K3: =E3/H3 -> #DIV/0!
A4: 45605 | B4: =TEXT(A4,"mmm-yy") -> Nov-24 | D4: GV2 Remote Main PCB | I4: Poonam lokhande | J4: Gv2 QC reparing ok pcb = 135 | K4: =E4/H4 -> #DIV/0!
A5: 45605 | B5: =TEXT(A5,"mmm-yy") -> Nov-24 | D5: GV3 Digital PCB | I5: Poonam lokhande | J5: Gv3 digital QC reparing pcb ok = 32 | K5: =E5/H5 -> #DIV/0!
A6: 45608 | B6: =TEXT(A6,"mmm-yy") -> Nov-24 | D6: GV3 Power PCB | E6: 120 | F6: 5 | H6: =SUM(E6:G6) -> 125 | I6: Nilam dhanawade | K6: =E6/H6 -> 0.96
A7: 45608 | B7: =TEXT(A7,"mmm-yy") -> Nov-24 | D7: GV3 Power PCB | E7: 80 | F7: 4 | H7: =SUM(E7:G7) -> 84 | I7: Amit ghabale | K7: =E7/H7 -> 0.95238095
A8: 45609 | B8: =TEXT(A8,"mmm-yy") -> Nov-24 | D8: GV3 Power PCB | E8: 170 | F8: 3 | H8: =SUM(E8:G8) -> 173 | I8: Akash prasad | K8: =E8/H8 -> 0.98265896
A9: 45609 | B9: =TEXT(A9,"mmm-yy") -> Nov-24 | D9: GV3 Power PCB | E9: 180 | F9: 7 | H9: =SUM(E9:G9) -> 187 | I9: Nilam dhanawade | K9: =E9/H9 -> 0.96256684
A10: 45609 | B10: =TEXT(A10,"mmm-yy") -> Nov-24 | D10: GV3 Power PCB | E10: 150 | F10: 2 | H10: =SUM(E10:G10) -> 152 | I10: Amit ghabale | K10: =E10/H10 -> 0.98684211
A11: 45610 | B11: =TEXT(A11,"mmm-yy") -> Nov-24 | D11: GV3 Power PCB | E11: 90 | F11: 6 | H11: =SUM(E11:G11) -> 96 | I11: Nilam dhanawade | K11: =E11/H11 -> 0.9375
A12: 45610 | B12: =TEXT(A12,"mmm-yy") -> Nov-24 | D12: GV3 Power PCB | E12: 50 | F12: 0 | H12: =SUM(E12:G12) -> 50 | I12: Akash prasad | K12: =E12/H12 -> 1
A13: 45610 | B13: =TEXT(A13,"mmm-yy") -> Nov-24 | D13: GV3 Power PCB | E13: 10 | H13: =SUM(E13:G13) -> 10 | I13: Mayuri | K13: =E13/H13 -> 1
A14: 45611 | B14: =TEXT(A14,"mmm-yy") -> Nov-24 | D14: GV3 Power PCB | E14: 180 | F14: 9 | H14: =SUM(E14:G14) -> 189 | I14: Nilam dhanawade | K14: =E14/H14 -> 0.95238095
A15: 45611 | B15: =TEXT(A15,"mmm-yy") -> Nov-24 | D15: GV3 Power PCB | E15: 170 | F15: 7 | H15: =SUM(E15:G15) -> 177 | I15: Akash prasad | K15: =E15/H15 -> 0.96045198
A16: 45611 | B16: =TEXT(A16,"mmm-yy") -> Nov-24 | D16: GV3 Power PCB | E16: 170 | F16: 8 | H16: =SUM(E16:G16) -> 178 | I16: Poonam lokhande | K16: =E16/H16 -> 0.95505618
A17: 45611 | B17: =TEXT(A17,"mmm-yy") -> Nov-24 | D17: GV3 Power PCB | E17: 50 | F17: 5 | H17: =SUM(E17:G17) -> 55 | I17: Mayuri | K17: =E17/H17 -> 0.90909091
A18: 45611 | B18: =TEXT(A18,"mmm-yy") -> Nov-24 | D18: GV3 Power PCB | E18: 175 | F18: 5 | H18: =SUM(E18:G18) -> 180 | I18: Amit ghabale | K18: =E18/H18 -> 0.97222222
A19: 45612 | B19: =TEXT(A19,"mmm-yy") -> Nov-24 | D19: GV3 Power PCB | E19: 100 | F19: 6 | H19: =SUM(E19:G19) -> 106 | I19: Nilam dhanawade | K19: =E19/H19 -> 0.94339623
A20: 45612 | B20: =TEXT(A20,"mmm-yy") -> Nov-24 | D20: GV2 Remote Main PCB | E20: 25 | F20: 2 | H20: =SUM(E20:G20) -> 27 | I20: Nilam dhanawade | K20: =E20/H20 -> 0.92592593
A21: 45612 | B21: =TEXT(A21,"mmm-yy") -> Nov-24 | D21: GV3 Power PCB | E21: 75 | F21: 5 | H21: =SUM(E21:G21) -> 80 | I21: Mayuri | K21: =E21/H21 -> 0.9375
A22: 45612 | B22: =TEXT(A22,"mmm-yy") -> Nov-24 | D22: GV3 Power PCB | E22: 90 | F22: 3 | H22: =SUM(E22:G22) -> 93 | I22: Akash prasad | K22: =E22/H22 -> 0.96774194
A23: 45612 | B23: =TEXT(A23,"mmm-yy") -> Nov-24 | D23: GV2 Remote Main PCB | E23: 40 | F23: 2 | H23: =SUM(E23:G23) -> 42 | I23: Akash prasad | K23: =E23/H23 -> 0.95238095
A24: 45612 | B24: =TEXT(A24,"mmm-yy") -> Nov-24 | D24: GV3 Digital PCB | E24: 140 | F24: 4 | H24: =SUM(E24:G24) -> 144 | I24: Swarupa Vishwakarma | K24: =E24/H24 -> 0.97222222
A25: 45612 | B25: =TEXT(A25,"mmm-yy") -> Nov-24 | D25: GV3 Power PCB | E25: 48 | H25: =SUM(E25:G25) -> 48 | I25: Poonam lokhande | K25: =E25/H25 -> 1
A26: 45612 | B26: =TEXT(A26,"mmm-yy") -> Nov-24 | D26: GV2 Regulator | H26: =SUM(E26:G26) -> 0 | I26: Poonam lokhande | J26: Gv2 QC reparing ok pcb =23 | K26: =E26/H26 -> #DIV/0!
A27: 45612 | B27: =TEXT(A27,"mmm-yy") -> Nov-24 | D27: GV3 Digital PCB | H27: =SUM(E27:G27) -> 0 | I27: Poonam lokhande | J27: Gv3 digital QC Reparing ok pcb = 28 | K27: =E27/H27 -> #DIV/0!
A28: 45612 | B28: =TEXT(A28,"mmm-yy") -> Nov-24 | D28: GV4 Ozeo Remote PCB | H28: =SUM(E28:G28) -> 0 | I28: Poonam lokhande | J28: Gv4 Reguleter QC reparing ok pcb = 65 | K28: =E28/H28 -> #DIV/0!
A29: 45612 | B29: =TEXT(A29,"mmm-yy") -> Nov-24 | D29: GV3 Power PCB | H29: =SUM(E29:G29) -> 0 | I29: Poonam lokhande | J29: Gv3 power QC reparing ok pcb = 36 | K29: =E29/H29 -> #DIV/0!
A30: 45612 | B30: =TEXT(A30,"mmm-yy") -> Nov-24 | D30: GV3 Power PCB | E30: 85 | F30: 2 | H30: =SUM(E30:G30) -> 87 | I30: Amit ghabale | K30: =E30/H30 -> 0.97701149
A31: 45612 | B31: =TEXT(A31,"mmm-yy") -> Nov-24 | D31: GV2 Regulator | E31: 30 | F31: 1 | H31: =SUM(E31:G31) -> 31 | I31: Amit ghabale | K31: =E31/H31 -> 0.96774194
A32: 45614 | B32: =TEXT(A32,"mmm-yy") -> Nov-24 | D32: GV2 Remote Main PCB | E32: 75 | F32: 6 | H32: =SUM(E32:G32) -> 81 | I32: Nilam dhanawade | K32: =E32/H32 -> 0.92592593
A33: 45614 | B33: =TEXT(A33,"mmm-yy") -> Nov-24 | D33: GV2 Remote Main PCB | E33: 75 | F33: 6 | H33: =SUM(E33:G33) -> 81 | I33: Akash prasad | K33: =E33/H33 -> 0.92592593
A34: 45614 | B34: =TEXT(A34,"mmm-yy") -> Nov-24 | D34: GV3 Power PCB | E34: 30 | H34: =SUM(E34:G34) -> 30 | I34: Mayuri | J34: Gv3 power debug +testing | K34: =E34/H34 -> 1
A35: 45615 | B35: =TEXT(A35,"mmm-yy") -> Nov-24 | D35: GV2 Remote Main PCB | E35: 80 | F35: 9 | H35: =SUM(E35:G35) -> 89 | I35: Nilam dhanawade | K35: =E35/H35 -> 0.8988764
A36: 45615 | B36: =TEXT(A36,"mmm-yy") -> Nov-24 | D36: GV2 Remote Main PCB | E36: 75 | F36: 7 | H36: =SUM(E36:G36) -> 82 | I36: Akash prasad | K36: =E36/H36 -> 0.91463415
A37: 45615 | B37: =TEXT(A37,"mmm-yy") -> Nov-24 | D37: GV3 Digital PCB | E37: 150 | F37: 8 | H37: =SUM(E37:G37) -> 158 | I37: Rahul gupta | J37: Debag testing ok | K37: =E37/H37 -> 0.94936709
A38: 45615 | B38: =TEXT(A38,"mmm-yy") -> Nov-24 | D38: GV3 Digital PCB | E38: 30 | H38: =SUM(E38:G38) -> 30 | I38: Mayuri | J38: Debag testing ok | K38: =E38/H38 -> 1
A39: 45615 | B39: =TEXT(A39,"mmm-yy") -> Nov-24 | D39: GV2 Remote Main PCB | E39: 75 | F39: 2 | H39: =SUM(E39:G39) -> 77 | I39: Amit ghabale | K39: =E39/H39 -> 0.97402597
A40: 45615 | B40: =TEXT(A40,"mmm-yy") -> Nov-24 | D40: GV2 Remote Main PCB | E40: 75 | F40: 8 | H40: =SUM(E40:G40) -> 83 | I40: Poonam lokhande | J40: Debag testing ok | K40: =E40/H40 -> 0.90361446
...

Sheet Step6_Entry
A1: Date | B1: Month | C1: In_Lot | D1: PCB Type | E1: Entry Count | F1: PCB Status | G1: Operator Name
A2: 45605 | B2: =TEXT(A2,"mmm-yy") -> Nov-24 | D2: GV2 Remote Main PCB | E2: 235 | F2: QC Repairing | G2: Rahul gupta
A3: 45605 | B3: =TEXT(A3,"mmm-yy") -> Nov-24 | D3: GV3 Digital PCB | E3: 474 | F3: scrap pcb | G3: Rahul gupta
A4: 45607 | B4: =TEXT(A4,"mmm-yy") -> Nov-24 | D4: GV3 Power PCB | G4: Rahul gupta
A5: 45607 | B5: =TEXT(A5,"mmm-yy") -> Nov-24 | D5: GV4 Studio+ Remote PCB | E5: 525 | F5: scrap pcb | G5: Rahul gupta
A6: 45607 | B6: =TEXT(A6,"mmm-yy") -> Nov-24 | D6: GV2 Remote Main PCB | G6: Rahul gupta
A7: 45607 | B7: =TEXT(A7,"mmm-yy") -> Nov-24 | D7: GV3 Digital PCB | G7: Rahul gupta
A8: 45607 | B8: =TEXT(A8,"mmm-yy") -> Nov-24 | D8: GV4 Studio+ Remote PCB | E8: 150 | F8: QC Repairing | G8: Rahul gupta
A9: 45609 | B9: =TEXT(A9,"mmm-yy") -> Nov-24 | D9: GV3 Power PCB | E9: 200 | F9: debug pcb | G9: Rahul gupta
A10: 45611 | B10: =TEXT(A10,"mmm-yy") -> Nov-24 | D10: GV3 Power PCB | E10: 573 | F10: debug pcb | G10: Rahul gupta
A11: 45612 | B11: =TEXT(A11,"mmm-yy") -> Nov-24 | D11: GV3 Power PCB | E11: 683 | F11: debug pcb | G11: Rahul gupta
A12: 45614 | B12: =TEXT(A12,"mmm-yy") -> Nov-24 | D12: GV3 Power PCB | E12: 476 | F12: debug pcb | G12: Rahul gupta
A13: 45614 | B13: =TEXT(A13,"mmm-yy") -> Nov-24 | D13: GV3 Digital PCB | E13: 134 | F13: debug pcb | G13: Rahul gupta
A14: 45615 | B14: =TEXT(A14,"mmm-yy") -> Nov-24 | D14: GV3 Digital PCB | E14: 169 | F14: debug pcb | G14: Rahul gupta
A15: 45615 | B15: =TEXT(A15,"mmm-yy") -> Nov-24 | D15: GV2 Regulator | E15: 190 | F15: debug pcb | G15: Rahul gupta
A16: 45615 | B16: =TEXT(A16,"mmm-yy") -> Nov-24 | D16: GV4 Alpha Regulator PCB | E16: 56 | F16: QC Repairing | G16: Rahul gupta
A17: 45615 | B17: =TEXT(A17,"mmm-yy") -> Nov-24 | D17: GV2 Regulator | E17: 22 | F17: QC Repairing | G17: Rahul gupta
A18: 45615 | B18: =TEXT(A18,"mmm-yy") -> Nov-24 | D18: GV2 Regulator | E18: 51 | F18: 1 st level | G18: Rahul gupta
A19: 45615 | B19: =TEXT(A19,"mmm-yy") -> Nov-24 | D19: GV2 Remote Main PCB | E19: 37 | F19: 1 st level | G19: Rahul gupta
... A29: 45624 | B29: =TEXT(A29,"mmm-yy") -> Nov-24 | D29: GV2 Remote Main PCB | E29: 183 | F29: debug pcb | G29: Rahul gupta
A30: 45624 | B30: =TEXT(A30,"mmm-yy") -> Nov-24 | C30: 72 | D30: GV3 Power PCB | E30: 402 | F30: debug pcb | G30: Rahul gupta
A31: 45624 | B31: =TEXT(A31,"mmm-yy") -> Nov-24 | C31: 72 | D31: GV2 Remote Main PCB | E31: 30 | F31: 1 st level | G31: Rahul gupta
A32: 45624 | B32: =TEXT(A32,"mmm-yy") -> Nov-24 | C32: 72 | D32: GV2 Remote Main PCB | E32: 60 | F32: 1 st level | G32: Rahul gupta
A33: 45625 | B33: =TEXT(A33,"mmm-yy") -> Nov-24 | D33: GV2 Remote Main PCB | E33: 182 | F33: debug pcb | G33: Rahul gupta
A34: 45625 | B34: =TEXT(A34,"mmm-yy") -> Nov-24 | C34: 72 | D34: GV2 Remote Main PCB | E34: 48 | F34: debug pcb | G34: Rahul gupta
A35: 45628 | B35: =TEXT(A35,"mmm-yy") -> Dec-24 | D35: GV2 Regulator | E35: 202 | F35: debug pcb | G35: Rahul gupta
A36: 45629 | B36: =TEXT(A36,"mmm-yy") -> Dec-24 | D36: GV3 Digital PCB | E36: 25 | F36: QC Repairing | G36: Rahul gupta
A37: 45629 | B37: =TEXT(A37,"mmm-yy") -> Dec-24 | D37: GV3 Power PCB | E37: 74 | F37: QC Repairing | G37: Rahul gupta
A38: 45629 | B38: =TEXT(A38,"mmm-yy") -> Dec-24 | D38: GV3 Power PCB | E38: 134 | F38: scrap pcb | G38: Rahul gupta
A39: 45629 | B39: =TEXT(A39,"mmm-yy") -> Dec-24 | D39: GV3 Digital PCB | E39: 244 | F39: scrap pcb | G39: Rahul gupta
A40: 45629 | B40: =TEXT(A40,"mmm-yy") -> Dec-24 | C40: 72 | D40: GV3 Power PCB | E40: 49 | F40: scrap pcb | G40: Rahul gupta
A41: 45629 | B41: =TEXT(A41,"mmm-yy") -> Dec-24 | C41: 72 | D41: GV3 Digital PCB | E41: 188 | F41: scrap pcb | G41: Rahul gupta
A42: 45629 | B42: =TEXT(A42,"mmm-yy") -> Dec-24 | C42: 72 | D42: GV2 Remote Main PCB | E42: 134 | F42: scrap pcb | G42: Rahul gupta
A43: 45629 | B43: =TEXT(A43,"mmm-yy") -> Dec-24 | C43: 73 | D43: GV3 Digital PCB | E43: 89 | F43: scrap pcb | G43: Rahul gupta
A44: 45629 | B44: =TEXT(A44,"mmm-yy") -> Dec-24 | C44: 73 | D44: GV3 Power PCB | E44: 20 | F44: scrap pcb | G44: Rahul gupta
A45: 45629 | B45: =TEXT(A45,"mmm-yy") -> Dec-24 | C45: 73 | D45: GV2 Remote Main PCB | E45: 62 | F45: scrap pcb | G45: Rahul gupta
A46: 45630 | B46: =TEXT(A46,"mmm-yy") -> Dec-24 | D46: GV2 Remote Main PCB | E46: 133 | F46: debug pcb | G46: Rahul gupta
A47: 45630 | B47: =TEXT(A47,"mmm-yy") -> Dec-24 | C47: 73 | D47: GV3 Power PCB | E47: 209 | F47: debug pcb | G47: Rahul gupta
A48: 45630 | B48: =TEXT(A48,"mmm-yy") -> Dec-24 | C48: 73 | D48: GV3 Digital PCB | E48: 160 | F48: debug pcb | G48: Rahul gupta
A49: 45630 | B49: =TEXT(A49,"mmm-yy") -> Dec-24 | C49: 73 | D49: GV2 Remote Main PCB | E49: 286 | F49: 1 st level | G49: Rahul gupta
...

Sheet Step7_Cleaning
A1: Date | B1: Month | C1: In_Lot | D1: PCB Type | E1: Quantity Cleaned | F1: QC Reject | G1: Total PCBs | H1: Operator Name | I1: Remark
A2: 45601 | B2: =TEXT(A2,"mmm-yy") -> Nov-24 | D2: GV2 Remote Main PCB | E2: 401 | G2: =SUM(E2:F2) -> 401 | H2: Vijay kumar
A3: 45602 | B3: =TEXT(A3,"mmm-yy") -> Nov-24 | D3: GV2 Remote Main PCB | G3: =SUM(E3:F3) -> 0 | H3: Vijay kumar
A4: 45602 | B4: =TEXT(A4,"mmm-yy") -> Nov-24 | D4: GV4 Studio+ Remote PCB | G4: =SUM(E4:F4) -> 0 | H4: Vijay kumar
A5: 45602 | B5: =TEXT(A5,"mmm-yy") -> Nov-24 | D5: GV3 Digital PCB | E5: 557 | G5: =SUM(E5:F5) -> 557 | H5: Vijay kumar
A6: 45602 | B6: =TEXT(A6,"mmm-yy") -> Nov-24 | D6: GV3 Digital PCB | E6: 75 | G6: =SUM(E6:F6) -> 75 | H6: Rahul gupta
A7: 45603 | B7: =TEXT(A7,"mmm-yy") -> Nov-24 | D7: GV2 Remote Main PCB | G7: =SUM(E7:F7) -> 0
A8: 45604 | B8: =TEXT(A8,"mmm-yy") -> Nov-24 | D8: GV4 Studio+ Remote PCB | G8: =SUM(E8:F8) -> 0
A9: 45604 | B9: =TEXT(A9,"mmm-yy") -> Nov-24 | D9: GV4 Alpha Regulator PCB | E9: 440 | G9: =SUM(E9:F9) -> 440 | H9: Vijay kumar
A10: 45605 | B10: =TEXT(A10,"mmm-yy") -> Nov-24 | D10: GV2 Remote Main PCB | G10: =SUM(E10:F10) -> 0 | H10: Vijay kumar
A11: 45605 | B11: =TEXT(A11,"mmm-yy") -> Nov-24 | D11: GV4 Studio+ Remote PCB | G11: =SUM(E11:F11) -> 0 | H11: Vijay kumar
A12: 45605 | B12: =TEXT(A12,"mmm-yy") -> Nov-24 | D12: GV3 Digital PCB | E12: 702 | G12: =SUM(E12:F12) -> 702 | H12: Vijay kumar
A13: 45607 | B13: =TEXT(A13,"mmm-yy") -> Nov-24 | D13: GV4 Studio+ Remote PCB | G13: =SUM(E13:F13) -> 0
A14: 45607 | B14: =TEXT(A14,"mmm-yy") -> Nov-24 | D14: GV3 Digital PCB | E14: 200 | G14: =SUM(E14:F14) -> 200 | H14: Nilam dhanawade
A15: 45607 | B15: =TEXT(A15,"mmm-yy") -> Nov-24 | D15: GV2 Remote Main PCB | G15: =SUM(E15:F15) -> 0
A16: 45607 | B16: =TEXT(A16,"mmm-yy") -> Nov-24 | D16: GV4 Studio+ Remote PCB | E16: 520 | G16: =SUM(E16:F16) -> 520 | H16: Vijay kumar
A17: 45608 | B17: =TEXT(A17,"mmm-yy") -> Nov-24 | D17: GV3 Digital PCB | E17: 180 | F17: 2 | G17: =SUM(E17:F17) -> 182 | H17: Rahul gupta
A18: 45608 | B18: =TEXT(A18,"mmm-yy") -> Nov-24 | D18: GV4 Alpha Regulator PCB | E18: 25 | G18: =SUM(E18:F18) -> 25 | H18: Rahul gupta
A19: 45608 | B19: =TEXT(A19,"mmm-yy") -> Nov-24 | D19: GV3 Digital PCB | E19: 180 | G19: =SUM(E19:F19) -> 180 | H19: Vijay kumar
A20: 45608 | B20: =TEXT(A20,"mmm-yy") -> Nov-24 | D20: GV4 Alpha Regulator PCB | E20: 130 | G20: =SUM(E20:F20) -> 130 | H20: Vijay kumar
A21: 45609 | B21: =TEXT(A21,"mmm-yy") -> Nov-24 | D21: GV2 Remote Main PCB | E21: 340 | G21: =SUM(E21:F21) -> 340 | H21: Vijay kumar
A22: 45609 | B22: =TEXT(A22,"mmm-yy") -> Nov-24 | D22: GV2 Regulator | E22: 205 | G22: =SUM(E22:F22) -> 205 | H22: Vijay kumar
A23: 45610 | B23: =TEXT(A23,"mmm-yy") -> Nov-24 | D23: GV3 Power PCB | E23: 200 | G23: =SUM(E23:F23) -> 200 | H23: Vijay kumar
A24: 45611 | B24: =TEXT(A24,"mmm-yy") -> Nov-24 | D24: GV3 Power PCB | E24: 465 | G24: =SUM(E24:F24) -> 465 | H24: Vijay kumar
A25: 45612 | B25: =TEXT(A25,"mmm-yy") -> Nov-24 | D25: GV3 Power PCB | E25: 510 | G25: =SUM(E25:F25) -> 510 | H25: Vijay kumar
A26: 45614 | B26: =TEXT(A26,"mmm-yy") -> Nov-24 | D26: GV3 Digital PCB | E26: 101 | G26: =SUM(E26:F26) -> 101 | H26: Rahul gupta
A27: 45615 | B27: =TEXT(A27,"mmm-yy") -> Nov-24 | D27: GV3 Power PCB | E27: 480 | G27: =SUM(E27:F27) -> 480 | H27: Vijay kumar
A28: 45615 | B28: =TEXT(A28,"mmm-yy") -> Nov-24 | D28: GV3 Digital PCB | E28: 50 | G28: =SUM(E28:F28) -> 50 | H28: Vijay kumar
A29: 45615 | B29: =TEXT(A29,"mmm-yy") -> Nov-24 | D29: GV3 Digital PCB | E29: 30 | G29: =SUM(E29:F29) -> 30 | H29: Rahul gupta
... A40: 45622 | B40: =TEXT(A40,"mmm-yy") -> Nov-24 | D40: GV4 Alpha Regulator PCB | E40: 64 | G40: =SUM(E40:F40) -> 64 | H40: Vijay kumar
A41: 45622 | B41: =TEXT(A41,"mmm-yy") -> Nov-24 | G41: =SUM(E41:F41) -> 0 | H41: Vijay kumar | I41: LORA PCB cleaning ok qty=200
A42: 45623 | B42: =TEXT(A42,"mmm-yy") -> Nov-24 | D42: GV2 Regulator | E42: 283 | G42: =SUM(E42:F42) -> 283 | H42: Vijay kumar
A43: 45623 | B43: =TEXT(A43,"mmm-yy") -> Nov-24 | D43: GV3 Digital PCB | E43: 150 | G43: =SUM(E43:F43) -> 150 | H43: Vijay kumar
A44: 45623 | B44: =TEXT(A44,"mmm-yy") -> Nov-24 | D44: GV4 Alpha Regulator PCB | E44: 37 | G44: =SUM(E44:F44) -> 37 | H44: Vijay kumar
A45: 45623 | B45: =TEXT(A45,"mmm-yy") -> Nov-24 | D45: GV4 Studio+ Remote PCB | E45: 17 | G45: =SUM(E45:F45) -> 17 | H45: Vijay kumar
A46: 45624 | B46: =TEXT(A46,"mmm-yy") -> Nov-24 | D46: GV2 Remote Main PCB | E46: 120 | G46: =SUM(E46:F46) -> 120 | H46: Mayuri
A47: 45624 | B47: =TEXT(A47,"mmm-yy") -> Nov-24 | C47: 72 | D47: GV3 Power PCB | E47: 100 | G47: =SUM(E47:F47) -> 100 | H47: Mayuri
A48: 45624 | B48: =TEXT(A48,"mmm-yy") -> Nov-24 | D48: GV2 Remote Main PCB | E48: 92 | G48: =SUM(E48:F48) -> 92 | H48: Vijay kumar
A49: 45624 | B49: =TEXT(A49,"mmm-yy") -> Nov-24 | C49: 72 | D49: GV3 Power PCB | E49: 409 | F49: 8 | G49: =SUM(E49:F49) -> 417 | H49: Vijay kumar
A50: 45625 | B50: =TEXT(A50,"mmm-yy") -> Nov-24 | D50: GV2 Remote Main PCB | E50: 110 | G50: =SUM(E50:F50) -> 110 | H50: Vijay kumar
...

Sheet Step8_QC_After_Cleaning
A1: Date | B1: Month | C1: In_Lot | D1: PCB Type | E1: Quantity Passed | F1: Quantity Failed | G1: Total Quantity | H1: Operator Name | I1: Remark
A2: 45600 | B2: =TEXT(A2,"mmm-yy") -> Nov-24 | D2: GV2 Remote Main PCB | E2: 400 | F2: 20 | G2: =SUM(E2:F2) -> 420 | H2: Prajkta Sutar
A3: 45602 | B3: =TEXT(A3,"mmm-yy") -> Nov-24 | D3: GV2 Remote Main PCB | E3: 532 | F3: 58 | G3: =SUM(E3:F3) -> 590 | H3: Amit ghabale
A4: 45602 | B4: =TEXT(A4,"mmm-yy") -> Nov-24 | D4: GV4 Studio+ Remote PCB | E4: 200 | F4: 35 | G4: =SUM(E4:F4) -> 235 | H4: Amit ghabale
A5: 45602 | B5: =TEXT(A5,"mmm-yy") -> Nov-24 | D5: GV3 Digital PCB | E5: 68 | F5: 7 | G5: =SUM(E5:F5) -> 75 | H5: Amit ghabale
A6: 45603 | B6: =TEXT(A6,"mmm-yy") -> Nov-24 | D6: GV2 Remote Main PCB | E6: 371 | F6: 65 | G6: =SUM(E6:F6) -> 436 | H6: Amit ghabale
A7: 45603 | B7: =TEXT(A7,"mmm-yy") -> Nov-24 | D7: GV3 Digital PCB | E7: 235 | F7: 25 | G7: =SUM(E7:F7) -> 260 | H7: Amit ghabale
A8: 45603 | B8: =TEXT(A8,"mmm-yy") -> Nov-24 | D8: GV4 Studio+ Remote PCB | E8: 30 | F8: 35 | G8: =SUM(E8:F8) -> 65 | H8: Amit ghabale
A9: 45607 | B9: =TEXT(A9,"mmm-yy") -> Nov-24 | D9: GV2 Remote Main PCB | E9: 364 | F9: 20 | G9: =SUM(E9:F9) -> 384 | H9: Prajkta Sutar
A10: 45607 | B10: =TEXT(A10,"mmm-yy") -> Nov-24 | D10: GV3 Digital PCB | E10: 374 | F10: 21 | G10: =SUM(E10:F10) -> 395 | H10: Prajkta Sutar
A11: 45607 | B11: =TEXT(A11,"mmm-yy") -> Nov-24 | D11: GV4 Studio+ Remote PCB | E11: 254 | F11: 20 | G11: =SUM(E11:F11) -> 274 | H11: Prajkta Sutar
A12: 45608 | B12: =TEXT(A12,"mmm-yy") -> Nov-24 | D12: GV4 Alpha Regulator PCB | E12: 322 | F12: 39 | G12: =SUM(E12:F12) -> 361 | H12: Prajkta Sutar
A13: 45608 | B13: =TEXT(A13,"mmm-yy") -> Nov-24 | D13: GV3 Digital PCB | E13: 100 | F13: 12 | G13: =SUM(E13:F13) -> 112 | H13: Prajkta Sutar
... A22: 45614 | B22: =TEXT(A22,"mmm-yy") -> Nov-24 | D22: GV3 Power PCB | E22: 165 | F22: 11 | G22: =SUM(E22:F22) -> 176 | H22: Prajkta Sutar
A23: 45615 | B23: =TEXT(A23,"mmm-yy") -> Nov-24 | D23: GV3 Power PCB | E23: 193 | G23: =SUM(E23:F23) -> 193 | H23: Prajkta Sutar
A24: 45615 | B24: =TEXT(A24,"mmm-yy") -> Nov-24 | D24: GV3 Power PCB | E24: 315 | G24: =SUM(E24:F24) -> 315 | H24: Prajkta Sutar
A25: 45619 | B25: =TEXT(A25,"mmm-yy") -> Nov-24 | D25: GV2 Regulator | E25: 36 | G25: =SUM(E25:F25) -> 36 | H25: Prajkta Sutar
A26: 45619 | B26: =TEXT(A26,"mmm-yy") -> Nov-24 | D26: GV2 Remote Main PCB | E26: 314 | F26: 8 | G26: =SUM(E26:F26) -> 322 | H26: Prajkta Sutar
A27: 45619 | B27: =TEXT(A27,"mmm-yy") -> Nov-24 | D27: GV3 Digital PCB | E27: 182 | F27: 10 | G27: =SUM(E27:F27) -> 192 | H27: Prajkta Sutar
A28: 45622 | B28: =TEXT(A28,"mmm-yy") -> Nov-24 | G28: =SUM(E28:F28) -> 0 | H28: Prajkta Sutar | I28: Lora PCB QC ok = 200
A29: 45622 | B29: =TEXT(A29,"mmm-yy") -> Nov-24 | D29: GV2 Remote Main PCB | E29: 30 | F29: 3 | G29: =SUM(E29:F29) -> 33 | H29: Prajkta Sutar
A30: 45623 | B30: =TEXT(A30,"mmm-yy") -> Nov-24 | D30: GV2 Remote Main PCB | E30: 499 | F30: 49 | G30: =SUM(E30:F30) -> 548 | H30: Prajkta Sutar
A31: 45623 | B31: =TEXT(A31,"mmm-yy") -> Nov-24 | D31: GV3 Digital PCB | E31: 130 | F31: 10 | G31: =SUM(E31:F31) -> 140 | H31: Prajkta Sutar
A32: 45623 | B32: =TEXT(A32,"mmm-yy") -> Nov-24 | C32: 72 | D32: GV3 Digital PCB | E32: 56 | G32: =SUM(E32:F32) -> 56 | H32: Prajkta Sutar
A33: 45624 | B33: =TEXT(A33,"mmm-yy") -> Nov-24 | D33: GV3 Power PCB | E33: 400 | F33: 5 | G33: =SUM(E33:F33) -> 405 | H33: Prajkta Sutar
A34: 45624 | B34: =TEXT(A34,"mmm-yy") -> Nov-24 | C34: 72 | D34: GV3 Power PCB | E34: 87 | F34: 9 | G34: =SUM(E34:F34) -> 96 | H34: Prajkta Sutar
A35: 45624 | B35: =TEXT(A35,"mmm-yy") -> Nov-24 | C35: 72 | D35: GV2 Remote Main PCB | E35: 53 | F35: 9 | G35: =SUM(E35:F35) -> 62 | H35: Prajkta Sutar
A36: 45628 | B36: =TEXT(A36,"mmm-yy") -> Dec-24 | D36: GV2 Remote Main PCB | E36: 200 | F36: 9 | G36: =SUM(E36:F36) -> 209 | H36: Amit ghabale
A37: 45628 | B37: =TEXT(A37,"mmm-yy") -> Dec-24 | D37: GV3 Digital PCB | E37: 390 | F37: 10 | G37: =SUM(E37:F37) -> 400 | H37: Prajkta Sutar
A38: 45630 | B38: =TEXT(A38,"mmm-yy") -> Dec-24 | D38: GV3 Power PCB | E38: 140 | F38: 3 | G38: =SUM(E38:F38) -> 143 | H38: Prajkta Sutar
A39: 45630 | B39: =TEXT(A39,"mmm-yy") -> Dec-24 | D39: GV2 Remote Main PCB | E39: 295 | F39: 69 | G39: =SUM(E39:F39) -> 364 | H39: Prajkta Sutar
A40: 45630 | B40: =TEXT(A40,"mmm-yy") -> Dec-24 | C40: 73 | D40: GV2 Remote Main PCB | E40: 98 | G40: =SUM(E40:F40) -> 98 | H40: Prajkta Sutar
A41: 45631 | B41: =TEXT(A41,"mmm-yy") -> Dec-24 | C41: 73 | D41: GV2 Remote Main PCB | E41: 225 | F41: 4 | G41: =SUM(E41:F41) -> 229 | H41: Akash prasad
A42: 45631 | B42: =TEXT(A42,"mmm-yy") -> Dec-24 | C42: 73 | D42: GV2 Remote Main PCB | E42: 283 | F42: 3 | G42: =SUM(E42:F42) -> 286 | H42: Akash prasad
A43: 45631 | B43: =TEXT(A43,"mmm-yy") -> Dec-24 | C43: 73 | D43: GV2 Remote Main PCB | E43: 105 | F43: 2 | G43: =SUM(E43:F43) -> 107 | H43: Akash prasad
A44: 45631 | B44: =TEXT(A44,"mmm-yy") -> Dec-24 | D44: GV3 Digital PCB | E44: 173 | F44: 15 | G44: =SUM(E44:F44) -> 188 | H44: Prajkta Sutar
A45: 45631 | B45: =TEXT(A45,"mmm-yy") -> Dec-24 | D45: GV3 Power PCB | E45: 81 | F45: 3 | G45: =SUM(E45:F45) -> 84 | H45: Prajkta Sutar
A46: 45632 | B46: =TEXT(A46,"mmm-yy") -> Dec-24 | C46: 73 | D46: GV3 Power PCB | E46: 600 | F46: 10 | G46: =SUM(E46:F46) -> 610 | H46: Akash prasad
A47: 45632 | B47: =TEXT(A47,"mmm-yy") -> Dec-24 | C47: 73 | D47: GV4 Studio+ Remote PCB | E47: 85 | G47: =SUM(E47:F47) -> 85 | H47: Akash prasad
A48: 45632 | B48: =TEXT(A48,"mmm-yy") -> Dec-24 | C48: 73 | D48: GV4 Ozeo Remote PCB | E48: 71 | F48: 3 | G48: =SUM(E48:F48) -> 74 | H48: Akash prasad
...

Sheet Step9_Marking_Coating
A1: Date | B1: Month | C1: In_Lot | D1: PCB Type | E1: Quantity Marked & Coated | F1: Operator Name | G1: Remark
A2: 45600 | B2: =TEXT(A2,"mmm-yy") -> Nov-24 | D2: GV2 Remote Main PCB | E2: 450 | F2: Prajkta Sutar
A3: 45602 | B3: =TEXT(A3,"mmm-yy") -> Nov-24 | D3: GV2 Remote Main PCB | E3: 532 | F3: Amit ghabale
A4: 45602 | B4: =TEXT(A4,"mmm-yy") -> Nov-24 | D4: GV4 Studio+ Remote PCB | E4: 200 | F4: Amit ghabale
A5: 45602 | B5: =TEXT(A6,"mmm-yy") -> Nov-24 | D5: GV3 Digital PCB | E5: 68 | F5: Amit ghabale
A6: 45602 | B6: =TEXT(A7,"mmm-yy") -> Nov-24 | D6: GV2 Remote Main PCB | E6: 371 | F6: Amit ghabale
A7: 45602 | B7: =TEXT(A8,"mmm-yy") -> Nov-24 | D7: GV3 Digital PCB | E7: 235 | F7: Amit ghabale
A8: 45602 | B8: =TEXT(A9,"mmm-yy") -> Nov-24 | D8: GV4 Studio+ Remote PCB | E8: 30 | F8: Amit ghabale
A9: 45607 | B9: =TEXT(A10,"mmm-yy") -> Nov-24 | D9: GV4 Studio+ Remote PCB | E9: 880 | F9: Rahul gupta | G9: Gv2/Gv3/gv4
A10: 45608 | B10: =TEXT(A11,"mmm-yy") -> Nov-24 | D10: GV4 Alpha Regulator PCB | E10: 322 | F10: Rahul gupta
A11: 45608 | B11: =TEXT(A12,"mmm-yy") -> Nov-24 | D11: GV3 Digital PCB | E11: 100 | F11: Rahul gupta
A12: 45609 | B12: =TEXT(A12,"mmm-yy") -> Nov-24 | D12: GV3 Digital PCB | E12: 310 | F12: Mayuri
A13: 45609 | B13: =TEXT(A13,"mmm-yy") -> Nov-24 | D13: GV3 Digital PCB | E13: 315 | F13: Prajkta Sutar
A14: 45609 | B14: =TEXT(A14,"mmm-yy") -> Nov-24 | D14: GV4 Studio+ Remote PCB | E14: 54 | F14: Prajkta Sutar
A15: 45609 | B15: =TEXT(A15,"mmm-yy") -> Nov-24 | D15: GV4 Alpha Regulator PCB | E15: 63 | F15: Prajkta Sutar
A16: 45609 | B16: =TEXT(A16,"mmm-yy") -> Nov-24 | D16: GV4 Alpha Regulator PCB | E16: 140 | F16: Prajkta Sutar
A17: 45610 | B17: =TEXT(A17,"mmm-yy") -> Nov-24 | D17: GV2 Regulator | E17: 102 | F17: Prajkta Sutar
A18: 45610 | B18: =TEXT(A18,"mmm-yy") -> Nov-24 | D18: GV2 Remote Main PCB | E18: 123 | F18: Prajkta Sutar
A19: 45611 | B19: =TEXT(A19,"mmm-yy") -> Nov-24 | D19: GV3 Power PCB | E19: 600 | F19: Prajkta Sutar
A20: 45612 | B20: =TEXT(A20,"mmm-yy") -> Nov-24 | D20: GV3 Power PCB | E20: 352 | F20: Prajkta Sutar
A21: 45614 | B21: =TEXT(A21,"mmm-yy") -> Nov-24 | D21: GV3 Power PCB | E21: 150 | F21: Rahul gupta
A22: 45618 | B22: =TEXT(A22,"mmm-yy") -> Nov-24 | D22: GV2 Regulator | E22: 102 | F22: Vijay kumar
A23: 45619 | B23: =TEXT(A23,"mmm-yy") -> Nov-24 | D23: GV2 Regulator | E23: 496 | F23: Vijay kumar
... A32: 45671 | B32: =TEXT(A32,"mmm-yy") -> Jan-25 | D32: GV2 Remote Main PCB | E32: 205 | F32: Prajkta Sutar
A33: 45677 | B33: =TEXT(A33,"mmm-yy") -> Jan-25 | D33: All pcb | E33: 758 | F33: Prajkta Sutar | G33: amit
A34: 45681 | B34: =TEXT(A34,"mmm-yy") -> Jan-25 | D34: GV3 Digital PCB | E34: 420 | F34: Prajkta Sutar

Sheet Step10_Final_Testing
A1: Date | B1: Month | C1: In_Lot | D1: PCB Type | E1: Quantity Passed | F1: Quantity Failed | G1: Total Quantity | H1: Operator Name | I1: Remark
A2: 45600 | B2: =TEXT(A2,"mmm-yy") -> Nov-24 | D2: GV2 Remote Main PCB | E2: 270 | F2: 25 | G2: =SUM(E2:F2) -> 295 | H2: Swarupa Vishwakarma
A3: 45600 | B3: =TEXT(A3,"mmm-yy") -> Nov-24 | D3: GV2 Remote Main PCB | E3: 280 | F3: 30 | G3: =SUM(E3:F3) -> 310 | H3: Amit ghabale
A4: 45601 | B4: =TEXT(A4,"mmm-yy") -> Nov-24 | D4: GV2 Remote Main PCB | E4: 290 | F4: 21 | G4: =SUM(E4:F4) -> 311 | H4: Poonam lokhande
A5: 45601 | B5: =TEXT(A5,"mmm-yy") -> Nov-24 | D5: GV2 Remote Main PCB | E5: 340 | F5: 23 | G5: =SUM(E5:F5) -> 363 | H5: Swarupa Vishwakarma
A6: 45602 | B6: =TEXT(A6,"mmm-yy") -> Nov-24 | D6: GV2 Remote Main PCB | E6: 320 | F6: 18 | G6: =SUM(E6:F6) -> 338 | H6: Poonam lokhande
A7: 45603 | B7: =TEXT(A7,"mmm-yy") -> Nov-24 | D7: GV2 Remote Main PCB | E7: 348 | F7: 16 | G7: =SUM(E7:F7) -> 364 | H7: Swarupa Vishwakarma
A8: 45603 | B8: =TEXT(A8,"mmm-yy") -> Nov-24 | D8: GV2 Remote Main PCB | E8: 300 | F8: 14 | G8: =SUM(E8:F8) -> 314 | H8: Poonam lokhande
A9: 45603 | B9: =TEXT(A9,"mmm-yy") -> Nov-24 | D9: GV4 Studio+ Remote PCB | E9: 253 | F9: 17 | G9: =SUM(E9:F9) -> 270 | H9: Prajkta Sutar
A10: 45604 | B10: =TEXT(A10,"mmm-yy") -> Nov-24 | D10: GV2 Remote Main PCB | E10: 360 | F10: 8 | G10: =SUM(E10:F10) -> 368 | H10: Swarupa Vishwakarma
A11: 45604 | B11: =TEXT(A11,"mmm-yy") -> Nov-24 | D11: GV3 Digital PCB | E11: 250 | F11: 12 | G11: =SUM(E11:F11) -> 262 | H11: Akash prasad
A12: 45605 | B12: =TEXT(A12,"mmm-yy") -> Nov-24 | D12: GV2 Remote Main PCB | E12: 171 | F12: 7 | G12: =SUM(E12:F12) -> 178 | H12: Swarupa Vishwakarma
A13: 45605 | B13: =TEXT(A13,"mmm-yy") -> Nov-24 | D13: GV2 Remote Main PCB | E13: 35 | G13: =SUM(E13:F13) -> 35 | H13: Poonam lokhande
A14: 45607 | B14: =TEXT(A14,"mmm-yy") -> Nov-24 | D14: GV2 Remote Main PCB | E14: 250 | F14: 200 | G14: =SUM(E14:F14) -> 450 | H14: Swarupa Vishwakarma
A15: 45608 | B15: =TEXT(A15,"mmm-yy") -> Nov-24 | D15: GV4 Alpha Regulator PCB | E15: 230 | F15: 4 | G15: =SUM(E15:F15) -> 234 | H15: Akash prasad
A16: 45608 | B16: =TEXT(A16,"mmm-yy") -> Nov-24 | D16: GV3 Digital PCB | E16: 210 | F16: 6 | G16: =SUM(E16:F16) -> 216 | H16: Poonam lokhande
A17: 45608 | B17: =TEXT(A17,"mmm-yy") -> Nov-24 | D17: GV2 Remote Main PCB | E17: 216 | F17: 10 | G17: =SUM(E17:F17) -> 226 | H17: Swarupa Vishwakarma
A18: 45609 | B18: =TEXT(A18,"mmm-yy") -> Nov-24 | D18: GV3 Digital PCB | E18: 405 | F18: 11 | G18: =SUM(E18:F18) -> 416 | H18: Poonam lokhande
A19: 45609 | B19: =TEXT(A19,"mmm-yy") -> Nov-24 | D19: GV4 Alpha Regulator PCB | E19: 380 | F19: 20 | G19: =SUM(E19:F19) -> 400 | H19: Swarupa Vishwakarma
A20: 45610 | B20: =TEXT(A20,"mmm-yy") -> Nov-24 | D20: GV3 Digital PCB | E20: 41 | F20: 0 | G20: =SUM(E20:F20) -> 41 | H20: Poonam lokhande
A21: 45610 | B21: =TEXT(A21,"mmm-yy") -> Nov-24 | D21: GV4 Alpha Regulator PCB | E21: 88 | F21: 9 | G21: =SUM(E21:F21) -> 97 | H21: Swarupa Vishwakarma
A22: 45610 | B22: =TEXT(A22,"mmm-yy") -> Nov-24 | D22: GV4 Studio+ Remote PCB | E22: 80 | F22: 11 | G22: =SUM(E22:F22) -> 91 | H22: Swarupa Vishwakarma
A23: 45610 | B23: =TEXT(A23,"mmm-yy") -> Nov-24 | D23: GV4 Ozeo Remote PCB | E23: 4 | F23: 1 | G23: =SUM(E23:F23) -> 5 | H23: Swarupa Vishwakarma
A24: 45610 | B24: =TEXT(A24,"mmm-yy") -> Nov-24 | D24: GV2 Remote Main PCB | E24: 153 | F24: 8 | G24: =SUM(E24:F24) -> 161 | H24: Swarupa Vishwakarma
A25: 45611 | B25: =TEXT(A25,"mmm-yy") -> Nov-24 | D25: GV2 Regulator | E25: 76 | G25: =SUM(E25:F25) -> 76 | H25: Swarupa Vishwakarma
A26: 45611 | B26: =TEXT(A26,"mmm-yy") -> Nov-24 | D26: GV2 Remote Main PCB | E26: 182 | F26: 5 | G26: =SUM(E26:F26) -> 187 | H26: Swarupa Vishwakarma
A27: 45611 | B27: =TEXT(A27,"mmm-yy") -> Nov-24 | D27: GV2 Remote Main PCB | E27: 31 | G27: =SUM(E27:F27) -> 31 | H27: Swarupa Vishwakarma | I27: Gv2 QC faulty Repairing testing ok
A28: 45611 | B28: =TEXT(A28,"mmm-yy") -> Nov-24 | D28: GV3 Power PCB | E28: 10 | G28: =SUM(E28:F28) -> 10 | H28: Swarupa Vishwakarma | I28: Gv3 powar pcb Repairing ok
A29: 45617 | B29: =TEXT(A29,"mmm-yy") -> Nov-24 | D29: GV3 Digital PCB | E29: 190 | F29: 2 | G29: =SUM(E29:F29) -> 192 | H29: Akash prasad
A30: 45617 | B30: =TEXT(A30,"mmm-yy") -> Nov-24 | D30: GV3 Power PCB | E30: 300 | F30: 2 | G30: =SUM(E30:F30) -> 302 | H30: Akash prasad
A31: 45617 | B31: =TEXT(A31,"mmm-yy") -> Nov-24 | D31: GV3 Power PCB | E31: 612 | F31: 5 | G31: =SUM(E31:F31) -> 617 | H31: Poonam lokhande
A32: 45617 | B32: =TEXT(A32,"mmm-yy") -> Nov-24 | D32: GV3 Power PCB | E32: 481 | F32: 3 | G32: =SUM(E32:F32) -> 484 | H32: Prajkta Sutar
A33: 45618 | B33: =TEXT(A33,"mmm-yy") -> Nov-24 | D33: GV3 Power PCB | E33: 129 | F33: 2 | G33: =SUM(E33:F33) -> 131 | H33: Swarupa Vishwakarma | I33: Gv3 powar black
A34: 45618 | B34: =TEXT(A34,"mmm-yy") -> Nov-24 | D34: GV3 Power PCB | E34: 327 | F34: 9 | G34: =SUM(E34:F34) -> 336 | H34: Swarupa Vishwakarma | I34: Gv3 powar white
A35: 45618 | B35: =TEXT(A35,"mmm-yy") -> Nov-24 | D35: GV3 Digital PCB | E35: 71 | F35: 9 | G35: =SUM(E35:F35) -> 80 | H35: Swarupa Vishwakarma
A36: 45618 | B36: =TEXT(A36,"mmm-yy") -> Nov-24 | D36: GV2 Remote Main PCB | E36: 86 | F36: 6 | G36: =SUM(E36:F36) -> 92 | H36: Swarupa Vishwakarma
A37: 45619 | B37: =TEXT(A37,"mmm-yy") -> Nov-24 | D37: GV2 Remote Main PCB | E37: 35 | F37: 1 | G37: =SUM(E37:F37) -> 36 | H37: Swarupa Vishwakarma
A38: 45622 | B38: =TEXT(A38,"mmm-yy") -> Nov-24 | D38: GV2 Remote Main PCB | E38: 320 | F38: 24 | G38: =SUM(E38:F38) -> 344 | H38: Nilam dhanawade
A39: 45622 | B39: =TEXT(A39,"mmm-yy") -> Nov-24 | D39: GV3 Digital PCB | E39: 152 | F39: 143 | G39: =SUM(E39:F39) -> 295 | H39: Prajkta Sutar
A40: 45623 | B40: =TEXT(A40,"mmm-yy") -> Nov-24 | D40: GV2 Remote Main PCB | E40: 152 | F40: 5 | G40: =SUM(E40:F40) -> 157 | H40: Nilam dhanawade
...

Sheet Step11_Packing
A1: Date | B1: Month | C1: In_Lot | D1: PCB Type | E1: Bubble Packed | F1: Box Packed | G1: Operator Name | H1: Remark | I1: Out_Lot | J1: Date | K1: Month
A2: 45601 | B2: =TEXT(A2,"mmm-yy") -> Nov-24 | D2: GV2 Remote Main PCB | E2: 500 | G2: Amit ghabale
A3: 45602 | B3: =TEXT(A3,"mmm-yy") -> Nov-24 | D3: GV2 Remote Main PCB | E3: 100 | G3: Poonam lokhande
A4: 45603 | B4: =TEXT(A4,"mmm-yy") -> Nov-24 | D4: GV3 Power PCB | G4: Rahul gupta | H4: 510 pcb screw and mountaim plate open
A5: 45603 | B5: =TEXT(A5,"mmm-yy") -> Nov-24 | D5: GV2 Remote Main PCB | E5: 490 | G5: Mayuri
A6: 45603 | B6: =TEXT(A6,"mmm-yy") -> Nov-24 | D6: GV3 Power PCB | G6: Mayuri | H6: 210 pcbscrew and mountain plate open
A7: 45604 | B7: =TEXT(A7,"mmm-yy") -> Nov-24 | D7: GV3 Power PCB | G7: Mayuri | H7: Gv3 power 3 screw open & segregation qty_313
A8: 45604 | B8: =TEXT(A8,"mmm-yy") -> Nov-24 | D8: GV2 Remote Main PCB | E8: 290 | G8: Mayuri
A9: 45604 | B9: =TEXT(A9,"mmm-yy") -> Nov-24 | D9: GV4 Studio+ Remote PCB | G9: Mayuri | H9: Gv4 pcb 3 screw open & segregation qty_241
A10: 45604 | B10: =TEXT(A10,"mmm-yy") -> Nov-24 | D10: GV3 Power PCB | G10: Vijay kumar | H10: Gv3 power 3 screw open & segregation qty_317
A11: 45604 | B11: =TEXT(A11,"mmm-yy") -> Nov-24 | D11: GV2 Remote Main PCB | E11: 301 | G11: Vijay kumar
A12: 45604 | B12: =TEXT(A12,"mmm-yy") -> Nov-24 | D12: GV3 Power PCB | G12: Akash prasad | H12: Gv4 pcb 3 screw open & segregation qty_241
A13: 45604 | B13: =TEXT(A13,"mmm-yy") -> Nov-24 | D13: GV3 Power PCB | G13: Rahul gupta | H13: Gv3 power 3 screw open & segregation qty_309
A14: 45604 | B14: =TEXT(A14,"mmm-yy") -> Nov-24 | D14: GV2 Remote Main PCB | G14: Rahul gupta
A15: 45604 | B15: =TEXT(A15,"mmm-yy") -> Nov-24 | D15: GV4 Studio+ Remote PCB | E15: 282 | G15: Rahul gupta
A16: 45605 | B16: =TEXT(A16,"mmm-yy") -> Nov-24 | D16: GV3 Power PCB | G16: Rahul gupta | H16: Gv3 power 3 screw open qty_142
A17: 45608 | B17: =TEXT(A17,"mmm-yy") -> Nov-24 | D17: GV3 Digital PCB | G17: Rahul gupta | H17: Gv3 digital pcb box making qty_240
A18: 45608 | B18: =TEXT(A18,"mmm-yy") -> Nov-24 | D18: GV2 Remote Main PCB | F18: 2825 | G18: All
A19: 45608 | B19: =TEXT(A19,"mmm-yy") -> Nov-24 | D19: GV4 Alpha Regulator PCB | F19: 240 | G19: All | H19: 3065 pcb box packing all employee
A20: 45609 | B20: =TEXT(A20,"mmm-yy") -> Nov-24 | D20: GV4 Alpha Regulator PCB | E20: 227 | G20: Rahul gupta
A21: 45609 | B21: =TEXT(A21,"mmm-yy") -> Nov-24 | D21: GV2 Remote Main PCB | E21: 115 | G21: Rahul gupta
A22: 45610 | B22: =TEXT(A22,"mmm-yy") -> Nov-24 | D22: GV3 Digital PCB | E22: 340 | G22: Poonam lokhande
A23: 45610 | B23: =TEXT(A23,"mmm-yy") -> Nov-24 | F23: 3300 | G23: All | H23: Amazon Box Packing PCB =3300 Amit/rahul/Aakash
A24: 45610 | B24: =TEXT(A24,"mmm-yy") -> Nov-24 | D24: GV2 Remote Main PCB | G24: Vijay kumar | H24: Gv2 Box making qty 450
A25: 45610 | B25: =TEXT(A24,"mmm-yy") -> Nov-24 | D25: GV3 Power PCB | G25: Vijay kumar | H25: Gv3 Box making _600
A26: 45610 | B26: =TEXT(A25,"mmm-yy") -> Nov-24 | D26: GV3 Digital PCB | E26: 340 | G26: Mayuri
A27: 45611 | B27: =TEXT(A26,"mmm-yy") -> Nov-24 | I27: 27 | J27: 45611 | K27: Nov
A28: 45614 | B28: =TEXT(A27,"mmm-yy") -> Nov-24 | D28: GV3 Power PCB | G28: Mayuri | H28: 193 Gv3 power 3 screw fitting
A29: 45614 | B29: =TEXT(A28,"mmm-yy") -> Nov-24 | D29: GV3 Power PCB | G29: Prajkta Sutar | H29: 193 Gv3 power 3 screw fitting
A30: 45617 | B30: =TEXT(A29,"mmm-yy") -> Nov-24 | D30: GV3 Power PCB | G30: Rahul gupta | H30: Gv3 power maunting plate & 6 screw fitting qty_800
A31: 45617 | B31: =TEXT(A30,"mmm-yy") -> Nov-24 | D31: GV3 Power PCB | G31: Amit ghabale | H31: Gv3 power maunting plate & 6 screw fitting qty_800
A32: 45617 | B32: =TEXT(A31,"mmm-yy") -> Nov-24 | D32: GV3 Power PCB | G32: Vijay kumar | H32: Gv3 power maunting plate & 6 screw fitting qty_800
A33: 45618 | B33: =TEXT(A32,"mmm-yy") -> Nov-24 | D33: GV2 Regulator | G33: Rahul gupta | H33: Gv2 pcb box making qty_417
A34: 45618 | B34: =TEXT(A33,"mmm-yy") -> Nov-24 | D34: GV3 Power PCB | G34: Vijay kumar | H34: GV3 power 3 screw Fitting qty_90
A35: 45618 | B35: =TEXT(A34,"mmm-yy") -> Nov-24 | D35: GV3 Power PCB | G35: Vijay kumar | H35: Gv3 power box making qty_750
A36: 45618 | B36: =TEXT(A35,"mmm-yy") -> Nov-24 | D36: GV3 Digital PCB | G36: Vijay kumar | H36: Gv3 digital box making qty_275
A37: 45618 | B37: =TEXT(A36,"mmm-yy") -> Nov-24 | D37: GV3 Power PCB | G37: Nilam dhanawade | H37: Gv3 Power PCB Box Packing =1860
A38: 45618 | B38: =TEXT(A37,"mmm-yy") -> Nov-24 | D38: GV3 Digital PCB | G38: Amit ghabale | H38: Gv3 Digital Babble Shit + Box Packing =252
A39: 45618 | B39: =TEXT(A38,"mmm-yy") -> Nov-24 | D39: GV2 Regulator | G39: Mayuri | H39: Gv2 STM PCB Babble Shit +Box Packing =182
A40: 45618 | B40: =TEXT(A39,"mmm-yy") -> Nov-24 | D40: GV2 Remote Main PCB | G40: Poonam lokhande | H40: Gv2 Nuvton PCB Babble Shit + Box Packing =272
...

Sheet Step12_Final Entry
A1: Date | B1: Month | C1: In_Lot | D1: PCB Type | E1: Entry Count | F1: PCB Status | G1: Operator Name
A2: 45601 | B2: =TEXT(A2,"mmm-yy") -> Nov-24 | D2: GV2 Remote Main PCB | E2: 720 | F2: OK PCB | G2: Rahul gupta
A3: 45602 | B3: =TEXT(A3,"mmm-yy") -> Nov-24 | D3: GV2 Remote Main PCB | E3: 634 | F3: OK PCB | G3: Rahul gupta
A4: 45603 | B4: =TEXT(A4,"mmm-yy") -> Nov-24 | D4: GV2 Remote Main PCB | E4: 584 | F4: OK PCB | G4: Rahul gupta
A5: 45604 | B5: =TEXT(A5,"mmm-yy") -> Nov-24 | D5: GV2 Remote Main PCB | E5: 384 | F5: OK PCB | G5: Rahul gupta
A6: 45604 | B6: =TEXT(A6,"mmm-yy") -> Nov-24 | D6: GV4 Alpha Regulator PCB | E6: 240 | F6: OK PCB | G6: Rahul gupta
A7: 45605 | B7: =TEXT(A7,"mmm-yy") -> Nov-24 | D7: GV2 Remote Main PCB | E7: 523 | F7: OK PCB | G7: Rahul gupta
A8: 45605 | B8: =TEXT(A8,"mmm-yy") -> Nov-24 | D8: GV3 Digital PCB | E8: 240 | F8: OK PCB | G8: Rahul gupta
A9: 45607 | B9: =TEXT(A9,"mmm-yy") -> Nov-24 | D9: GV2 Remote Main PCB | E9: 250 | F9: OK PCB | G9: Rahul gupta
A10: 45609 | B10: =TEXT(A10,"mmm-yy") -> Nov-24 | D10: GV4 Alpha Regulator PCB | E10: 227 | F10: OK PCB | G10: Rahul gupta
A11: 45609 | B11: =TEXT(A11,"mmm-yy") -> Nov-24 | D11: GV2 Remote Main PCB | E11: 203 | F11: OK PCB | G11: Rahul gupta
A12: 45610 | B12: =TEXT(A12,"mmm-yy") -> Nov-24 | D12: GV3 Digital PCB | E12: 683 | F12: OK PCB | G12: Rahul gupta
A13: 45610 | B13: =TEXT(A13,"mmm-yy") -> Nov-24 | D13: GV4 Alpha Regulator PCB | E13: 480 | F13: OK PCB | G13: Rahul gupta
... A23: 45625 | B23: =TEXT(A23,"mmm-yy") -> Nov-24 | D23: GV2 Remote Main PCB | E23: 65 | F23: OK PCB | G23: Rahul gupta
A24: 45625 | B24: =TEXT(A24,"mmm-yy") -> Nov-24 | C24: 72 | D24: GV3 Digital PCB | E24: 141 | F24: OK PCB | G24: Rahul gupta
A25: 45626 | B25: =TEXT(A25,"mmm-yy") -> Nov-24 | D25: GV2 Remote Main PCB | E25: 580 | F25: OK PCB | G25: Rahul gupta
A26: 45628 | B26: =TEXT(A26,"mmm-yy") -> Dec-24 | C26: 73 | D26: GV3 Digital PCB | E26: 126 | F26: OK PCB | G26: Rahul gupta
A27: 45628 | B27: =TEXT(A27,"mmm-yy") -> Dec-24 | C27: 73 | D27: GV2 Remote Main PCB | E27: 160 | F27: OK PCB | G27: Rahul gupta
A28: 45629 | B28: =TEXT(A28,"mmm-yy") -> Dec-24 | D28: GV3 Digital PCB | E28: 192 | F28: OK PCB | G28: Rahul gupta
A29: 45630 | B29: =TEXT(A29,"mmm-yy") -> Dec-24 | C29: 73 | D29: GV2 Remote Main PCB | E29: 534 | F29: OK PCB | G29: Rahul gupta
A30: 45633 | B30: =TEXT(A30,"mmm-yy") -> Dec-24 | C30: 73 | D30: GV3 Digital PCB | E30: 158 | F30: OK PCB | G30: Rahul gupta
A31: 45633 | B31: =TEXT(A31,"mmm-yy") -> Dec-24 | C31: 73 | D31: GV2 Remote Main PCB | E31: 452 | F31: OK PCB | G31: Rahul gupta
A32: 45633 | B32: =TEXT(A32,"mmm-yy") -> Dec-24 | C32: 72 | D32: GV4 Studio+ Remote PCB | E32: 85 | F32: OK PCB | G32: Rahul gupta
A33: 45633 | B33: =TEXT(A33,"mmm-yy") -> Dec-24 | C33: 72 | D33: GV4 Ozeo Remote PCB | E33: 69 | F33: OK PCB | G33: Rahul gupta
A34: 45635 | B34: =TEXT(A34,"mmm-yy") -> Dec-24 | D34: GV2 Remote Main PCB | E34: 144 | F34: OK PCB | G34: Rahul gupta
A35: 45635 | B35: =TEXT(A35,"mmm-yy") -> Dec-24 | D35: GV4 Studio+ Remote PCB | E35: 18 | F35: OK PCB | G35: Rahul gupta
A36: 45635 | B36: =TEXT(A36,"mmm-yy") -> Dec-24 | D36: GV4 Alpha Regulator PCB | E36: 154 | F36: OK PCB | G36: Rahul gupta
A37: 45640 | B37: =TEXT(A37,"mmm-yy") -> Dec-24 | D37: GV2 Remote Main PCB | E37: 910 | F37: OK PCB | G37: Rahul gupta
A38: 45642 | B38: =TEXT(A38,"mmm-yy") -> Dec-24 | D38: GV2 Remote Main PCB | E38: 305 | F38: OK PCB | G38: Rahul gupta
A39: 45652 | B39: =TEXT(A39,"mmm-yy") -> Dec-24 | D39: GV2 Remote Main PCB | E39: 176 | F39: OK PCB | G39: Rahul gupta
A40: 45653 | B40: =TEXT(A40,"mmm-yy") -> Dec-24 | D40: GV4 Alpha Regulator PCB | E40: 147 | F40: OK PCB | G40: Rahul gupta
A41: 45653 | B41: =TEXT(A41,"mmm-yy") -> Dec-24 | D41: GV2 Remote Main PCB | E41: 158 | F41: OK PCB | G41: Rahul gupta
A42: 45653 | B42: =TEXT(A42,"mmm-yy") -> Dec-24 | D42: GV3 Digital PCB | E42: 275 | F42: OK PCB | G42: Rahul gupta
A43: 45654 | B43: =TEXT(A43,"mmm-yy") -> Dec-24 | D43: GV4 Alpha Regulator PCB | E43: 457 | F43: OK PCB | G43: Rahul gupta
A44: 45656 | B44: =TEXT(A44,"mmm-yy") -> Dec-24 | D44: GV3 Digital PCB | E44: 407 | F44: OK PCB | G44: Rahul gupta
A45: 45659 | B45: =TEXT(A45,"mmm-yy") -> Jan-25 | C45: 75/76 | D45: GV3 Digital PCB | E45: 445 | F45: OK PCB | G45: Rahul gupta
A46: 45659 | B46: =TEXT(A46,"mmm-yy") -> Jan-25 | C46: 74 | D46: GV2 Remote Main PCB | E46: 312 | F46: OK PCB | G46: Rahul gupta
A47: 45659 | B47: =TEXT(A47,"mmm-yy") -> Jan-25 | C47: 74 | D47: GV4 Studio+ Remote PCB | E47: 55 | F47: OK PCB | G47: Rahul gupta
A48: 45659 | B48: =TEXT(A48,"mmm-yy") -> Jan-25 | C48: 74 | D48: GV4 Ozeo Remote PCB | E48: 19 | F48: OK PCB | G48: Rahul gupta
A49: 45660 | B49: =TEXT(A49,"mmm-yy") -> Jan-25 | C49: 75/76 | D49: GV3 Digital PCB | E49: 308 | F49: OK PCB | G49: Rahul gupta
...

Sheet Dashboard
A1: Metric | B1: Value

Sheet Data Validation
B2: PCB Type | C2: Operator Name
B3: GV4 Ozeo Remote PCB | C3: Akash prasad
B4: GV3 Smart PCB | C4: Dadasaheb
B5: GV2 Regulator | C5: Amit ghabale
B6: GV3 Power PCB | C6: Lav sharma
B7: GV3 Digital PCB | C7: Nilam dhanawade
B8: GV2 Remote Main PCB | C8: Poonam lokhande
B9: GV4 Studio+ Remote PCB | C9: Prajkta Sutar
